<?xml version="1.0" encoding="utf-8"?>
<!-- ======================================================================= -->
<!-- Copyright 2024 MedCVR Lab                                               -->
<!-- ======================================================================= -->
<!-- This file contains the description of the Franka robot with LND tool.   -->
<!-- Adapted from the publicly available Franka URDF.                        -->
<!-- Franka + LND400006 Tool -->

<!-- ================= -->
<!--       Joints      -->
<!-- ================= -->
<robot name="franka_lnd">

  <joint name="world_base_joint" type="fixed">
    <parent link="world"/>
    <child link="panda_link0"/>
    <origin rpy="0 0 0" xyz="0 0 0"/>
  </joint>

  <joint name="panda_joint1" type="revolute">
    <safety_controller k_position="100.0" k_velocity="40.0" soft_lower_limit="-2.8973" soft_upper_limit="2.8973"/>
    <origin rpy="0 0 0" xyz="0 0 0.333"/>
    <parent link="panda_link0"/>
    <child link="panda_link1"/>
    <axis xyz="0 0 1"/>
    <limit acceleration="15" effort="87" lower="-2.9671" upper="2.9671" velocity="2.5"/>
    <dynamics D="1" K="7000" damping="0.003" friction="0.0" mu_coulomb="0" mu_viscous="16"/>
  </joint>

  <joint name="panda_joint2" type="revolute">
    <safety_controller k_position="100.0" k_velocity="40.0" soft_lower_limit="-1.7628" soft_upper_limit="1.7628"/>
    <origin rpy="-1.5707963267948966 0 0" xyz="0 0 0"/>
    <parent link="panda_link1"/>
    <child link="panda_link2"/>
    <axis xyz="0 0 1"/>
    <limit acceleration="7.5" effort="87" lower="-1.8326" upper="1.8326" velocity="2.5"/>
    <dynamics D="1" K="7000" damping="0.003" friction="0.0" mu_coulomb="0" mu_viscous="16"/>
  </joint>

  <joint name="panda_joint3" type="revolute">
    <safety_controller k_position="100.0" k_velocity="40.0" soft_lower_limit="-2.8973" soft_upper_limit="2.8973"/>
    <origin rpy="1.5707963267948966 0 0" xyz="0 -0.316 0"/>
    <parent link="panda_link2"/>
    <child link="panda_link3"/>
    <axis xyz="0 0 1"/>
    <limit acceleration="12.5" effort="87" lower="-2.9671" upper="2.9671" velocity="2.5"/>
    <dynamics D="1" K="7000" damping="0.003" friction="0.0" mu_coulomb="0" mu_viscous="16"/>
  </joint>

  <joint name="panda_joint4" type="revolute">
    <safety_controller k_position="100.0" k_velocity="40.0" soft_lower_limit="-3.0718" soft_upper_limit="-0.0698"/>
    <origin rpy="1.5707963267948966 0 0" xyz="0.0825 0 0"/>
    <parent link="panda_link3"/>
    <child link="panda_link4"/>
    <axis xyz="0 0 1"/>
    <limit acceleration="12.5" effort="87" lower="-3.1416" upper="-0.4" velocity="2.5"/>
    <dynamics D="1" K="7000" damping="0.003" friction="0.0" mu_coulomb="0" mu_viscous="16"/>
  </joint>

  <joint name="panda_joint5" type="revolute">
    <safety_controller k_position="100.0" k_velocity="40.0" soft_lower_limit="-2.8973" soft_upper_limit="2.8973"/>
    <origin rpy="-1.5707963267948966 0 0" xyz="-0.0825 0.384 0"/>
    <parent link="panda_link4"/>
    <child link="panda_link5"/>
    <axis xyz="0 0 1"/>
    <limit acceleration="15" effort="12" lower="-2.9671" upper="2.9671" velocity="3"/>
    <dynamics D="1" K="7000" damping="0.003" friction="0.0" mu_coulomb="0" mu_viscous="16"/>
  </joint>

  <joint name="panda_joint6" type="revolute">
    <safety_controller k_position="100.0" k_velocity="40.0" soft_lower_limit="-0.0175" soft_upper_limit="3.7525"/>
    <origin rpy="1.5707963267948966 0 0" xyz="0 0 0"/>
    <parent link="panda_link5"/>
    <child link="panda_link6"/>
    <axis xyz="0 0 1"/>
    <limit acceleration="20" effort="12" lower="-0.0873" upper="3.8223" velocity="3"/>
    <dynamics D="1" K="7000" damping="0.003" friction="0.0" mu_coulomb="0" mu_viscous="16"/>
  </joint>

  <joint name="panda_joint7" type="revolute">
    <safety_controller k_position="100.0" k_velocity="40.0" soft_lower_limit="-2.8973" soft_upper_limit="2.8973"/>
    <origin rpy="1.5707963267948966 0 0" xyz="0.088 0 0"/>
    <parent link="panda_link6"/>
    <child link="panda_link7"/>
    <axis xyz="0 0 1"/>
    <limit acceleration="20" effort="12" lower="-2.9671" upper="2.9671" velocity="3"/>
    <dynamics D="1" K="7000" damping="0.003" friction="0.0" mu_coulomb="0" mu_viscous="16"/>
  </joint>

  <joint name="franka_mount_joint" type="fixed">
    <origin rpy="0 0 3.14159" xyz="-0.0188 0 0.1915"/>
    <parent link="panda_link7"/>
    <child link="tool_mount_link"/>
  </joint>

  <joint name="tool_mount_joint" type="fixed">
    <origin rpy="0 0 0" xyz="0 0 0"/>
    <parent link="tool_mount_link"/>
    <child link="main_insertion_link"/>
  </joint>

  <joint name="tool_roll" type="revolute">
    <origin rpy="0 0 0" xyz="0 0 0.4162"/>
    <parent link="main_insertion_link"/>
    <child link="tool_roll_link"/>
    <axis xyz="0 0 1"/>
    <limit effort="1000" lower="-3.14159" upper="3.14159" velocity="10"/>
  </joint>

  <joint name="tool_pitch" type="revolute">
    <origin rpy="1.5708 -1.5708 0" xyz="0 0 0"/>
    <parent link="tool_roll_link"/>
    <child link="tool_pitch_link"/>
    <axis xyz="0 0 1"/>
    <limit effort="1000" lower="-1.5708" upper="1.5708" velocity="10"/>
  </joint>

  <joint name="tool_yaw" type="revolute">
    <origin rpy="-1.5708 1.5708 0" xyz="0.0091 0 0"/>
    <parent link="tool_pitch_link"/>
    <child link="tool_yaw_link"/>
    <axis xyz="0 0 1"/>
    <limit effort="1000" lower="-1.5708" upper="1.5708" velocity="10"/>
  </joint>

  <joint name="tool_gripper1_joint" type="revolute">
    <origin rpy="0 0 0" xyz="0 0 0"/>
    <parent link="tool_yaw_link"/>
    <child link="tool_gripper1_link"/>
    <axis xyz="0 0 1"/>
    <mimic joint="jaw" multiplier="-1" offset="0"/>
    <limit effort="0" lower="-1" upper="0" velocity="0"/>
  </joint>

  <joint name="jaw" type="revolute">
    <origin rpy="0 0 0" xyz="0 0 0"/>
    <parent link="tool_yaw_link"/>
    <child link="tool_gripper2_link"/>
    <axis xyz="0 0 1"/>
    <limit effort="0" lower="0" upper="1" velocity="0"/>
  </joint>

  <joint name="tool_tip_joint" type="fixed">
    <origin rpy="1.5708 1.5708 0" xyz="0 -0.0102 0"/>
    <parent link="tool_yaw_link"/>
    <child link="tool_tip"/>
  </joint>

  <!-- ================= -->
  <!--       Links       -->
  <!-- ================= -->

  <link name="world"/>

  <link name="panda_link0">
    <visual>
      <origin rpy="0 0 0" xyz="0 0 0"/>
      <geometry>
        <mesh filename="package://meshes/dae/link0.obj"/>
      </geometry>
    </visual>
    <inertial>
      <!-- Estimated guesses from CAD -->
      <origin rpy="0 0 0" xyz="-0.041018 -0.00014 0.049974"/>
      <mass value="0.629769"/>
      <inertia ixx="0.00315" ixy="8.2904E-07" ixz="0.00015" iyy="0.00388" iyz="8.2299E-06" izz="0.004285"/>
    </inertial>
  </link>
  <link name="panda_link1">
    <visual>
      <origin rpy="0 0 0" xyz="0 0 0"/>
      <geometry>
        <mesh filename="package://meshes/dae/link1.obj"/>
      </geometry>
    </visual>
    <inertial>
      <origin rpy="0 0 0" xyz="0.003875 0.002081 -0.04762"/>
      <mass value="4.970684"/>
      <inertia ixx="0.70337" ixy="-0.00013900" ixz="0.0067720" iyy="0.70661" iyz="0.019169" izz="0.0091170"/>
    </inertial>
  </link>

  <link name="panda_link2">
    <visual>
      <origin rpy="0 0 0" xyz="0 0 0"/>
      <geometry>
        <mesh filename="package://meshes/dae/link2.obj"/>
      </geometry>
    </visual>
    <inertial>
      <origin rpy="0 0 0" xyz=" -0.003141 -0.02872  0.003495"/>
      <mass value="0.646926"/>
      <inertia ixx="0.0079620" ixy="-3.9250e-3" ixz="1.0254e-02" iyy="2.8110e-02" iyz="7.0400e-04" izz="2.5995e-02"/>
    </inertial>
  </link>

  <link name="panda_link3">
    <visual>
      <origin rpy="0 0 0" xyz="0 0 0"/>
      <geometry>
        <mesh filename="package://meshes/dae/link3.obj"/>
      </geometry>
    </visual>
    <inertial>
      <origin rpy="0 0 0" xyz="2.7518e-02 3.9252e-02 -6.6502e-02"/>
      <mass value="3.228604"/>
      <inertia ixx="3.7242e-02" ixy="-4.7610e-03" ixz="-1.1396e-02" iyy="3.6155e-02" iyz="-1.2805e-02" izz="1.0830e-02"/>
    </inertial>
  </link>

  <link name="panda_link4">
    <visual>
      <origin rpy="0 0 0" xyz="0 0 0"/>
      <geometry>
        <mesh filename="package://meshes/dae/link4.obj"/>
      </geometry>
    </visual>
    <inertial>
      <origin rpy="0 0 0" xyz="-5.317e-02 1.04419e-01 2.7454e-02"/>
      <mass value="3.587895"/>
      <inertia ixx="2.5853e-02" ixy="7.7960e-03" ixz="-1.3320e-03" iyy="1.9552e-02" iyz="8.6410e-03" izz="2.8323e-02"/>
    </inertial>
  </link>

  <link name="panda_link5">
    <visual>
      <origin rpy="0 0 0" xyz="0 0 0"/>
      <geometry>
        <mesh filename="package://meshes/dae/link5.obj"/>
      </geometry>
    </visual>
    <inertial>
      <origin rpy="0 0 0" xyz="-1.1953e-02 4.1065e-02 -3.8437e-02"/>
      <mass value="1.225946"/>
      <inertia ixx="3.5549e-02" ixy="-2.1170e-03" ixz="-4.0370e-03" iyy="2.9474e-02" iyz="2.2900e-04" izz="8.6270e-03"/>
    </inertial>
  </link>

  <link name="panda_link6">
    <visual>
      <origin rpy="0 0 0" xyz="0 0 0"/>
      <geometry>
        <mesh filename="package://meshes/dae/link6.obj"/>
      </geometry>
    </visual>
    <inertial>
      <origin rpy="0 0 0" xyz="6.0149e-02 -1.4117e-02 -1.0517e-02"/>
      <mass value="1.666555"/>
      <inertia ixx="1.9640e-03" ixy="1.0900e-04" ixz="-1.1580e-03" iyy="4.3540e-03" iyz="3.4100e-04" izz="5.4330e-03"/>
    </inertial>
  </link>

  <link name="panda_link7">
    <visual>
      <origin rpy="0 0 0" xyz="0 0 0"/>
      <geometry>
        <mesh filename="package://meshes/dae/link7.obj"/>
      </geometry>
    </visual>
    <inertial>
      <origin rpy="0 0 0" xyz="1.0517e-02 -4.252e-03 6.1597e-02"/>
      <mass value="7.35522e-01"/>
      <inertia ixx="1.2516e-02" ixy="-4.2800e-04" ixz="-1.1960e-03" iyy="1.0027e-02" iyz="-7.4100e-04" izz="4.8150e-03"/>
    </inertial>
  </link>

  <link name="tool_mount_link">
    <visual>
      <origin rpy="0 0 0" xyz="0 0 0"/>
      <geometry>
        <mesh filename="package://meshes/obj/franka_tool_mount.obj"/>
      </geometry>
    </visual>
  </link>

  <link name="main_insertion_link">
    <inertial>
      <origin rpy="0 0 0" xyz="0.0040563 -0.00010934 0.0098616"/>
      <mass value="0.22491"/>
      <inertia ixx="0.01" ixy="-0.00001" ixz="0.00001" iyy="0.001" iyz="0.00001" izz="0.001"/>
    </inertial>
    <visual>
      <origin rpy="0 0 0" xyz="0 0 0"/>
      <geometry>
        <mesh filename="package://meshes/obj/tool_main_insertion_link.obj"/>
      </geometry>
      <material name="">
        <color rgba="0.3 0.3 0.3 1.0"/>
      </material>
    </visual>
    <collision name="main_insertion_link_collision_0">
      <origin rpy="0 0 0" xyz="0 0 0"/>
      <geometry>
        <mesh filename="package://meshes/obj/tool_main_insertion_link_collision_0.obj"/>
      </geometry>
    </collision>
    <collision name="main_insertion_link_collision_1">
      <origin rpy="0 0 0" xyz="0 0 0"/>
      <geometry>
        <mesh filename="package://meshes/obj/tool_main_insertion_link_collision_1.obj"/>
      </geometry>
    </collision>
  </link>

  <link name="tool_roll_link">
    <inertial>
      <origin rpy="0 0 0" xyz="0 0 -0.0058234"/>
      <mass value="0.00033225"/>
      <inertia ixx="0.001" ixy="0.00001" ixz="0.00001" iyy="0.001" iyz="0.00001" izz="0.001"/>
    </inertial>
    <visual>
      <origin rpy="0 0 0" xyz="0 0 0"/>
      <geometry>
        <mesh filename="package://meshes/obj/lnd_roll_link.obj"/>
      </geometry>
      <material name="">
        <color rgba="0.79608 0.82353 0.93725 1"/>
      </material>
    </visual>
    <collision name="tool_roll_link_collision_0">
      <origin rpy="0 0 0" xyz="0 0 0"/>
      <geometry>
        <mesh filename="package://meshes/obj/lnd_roll_link_collision_0.obj"/>
      </geometry>
    </collision>
    <collision name="tool_roll_link_collision_1">
      <origin rpy="0 0 0" xyz="0 0 0"/>
      <geometry>
        <mesh filename="package://meshes/obj/lnd_roll_link_collision_1.obj"/>
      </geometry>
    </collision>
    <collision name="tool_roll_link_collision_2">
      <origin rpy="0 0 0" xyz="0 0 0"/>
      <geometry>
        <mesh filename="package://meshes/obj/lnd_roll_link_collision_2.obj"/>
      </geometry>
    </collision>
  </link>


  <link name="tool_pitch_link">
    <inertial>
      <origin rpy="0 0 0" xyz="0.0035763 0 0"/>
      <mass value="0.00025784"/>
      <inertia ixx="0.001" ixy="0.00001" ixz="0.00001" iyy="0.001" iyz="0.00001" izz="0.001"/>
    </inertial>
    <visual>
      <origin rpy="0 0 0" xyz="0 0 0"/>
      <geometry>
        <mesh filename="package://meshes/obj/lnd_pitch_link.obj"/>
      </geometry>
      <material name="">
        <color rgba="0.79608 0.82353 0.93725 1"/>
      </material>
    </visual>
    <collision name="tool_pitch_link_collision_0">
      <origin rpy="0 0 0" xyz="0 0 0"/>
      <geometry>
        <mesh filename="package://meshes/obj/lnd_pitch_link_collision_0.obj"/>
      </geometry>
    </collision>
    <collision name="tool_pitch_link_collision_1">
      <origin rpy="0 0 0" xyz="0 0 0"/>
      <geometry>
        <mesh filename="package://meshes/obj/lnd_pitch_link_collision_1.obj"/>
      </geometry>
    </collision>
    <collision name="tool_pitch_link_collision_2">
      <origin rpy="0 0 0" xyz="0 0 0"/>
      <geometry>
        <mesh filename="package://meshes/obj/lnd_pitch_link_collision_2.obj"/>
      </geometry>
    </collision>
  </link>

  <link name="tool_yaw_link">
    <inertial>
      <origin rpy="0 0 0" xyz="0 0 0"/>
      <mass value="0.012491"/>
      <inertia ixx="0.001" ixy="0.00001" ixz="0.00001" iyy="0.001" iyz="0.00001" izz="0.001"/>
    </inertial>
    <visual>
      <origin rpy="0 0 0" xyz="0 0 0"/>
      <geometry>
        <mesh filename="package://meshes/obj/lnd_yaw_link.obj"/>
      </geometry>
      <material name="">
        <color rgba="0.79608 0.82353 0.93725 1"/>
      </material>
    </visual>
  </link>

  <link name="tool_gripper1_link">
    <inertial>
      <origin rpy="0 0 0" xyz="0.00019605 0.001435 -0.00088478"/>
      <mass value="0.010491"/>
      <inertia ixx="0.001" ixy="0.00001" ixz="0.00001" iyy="0.001" iyz="0.00001" izz="0.001"/>
    </inertial>
    <visual>
      <origin rpy="0 0 0" xyz="0 0 0"/>
      <geometry>
        <mesh filename="package://meshes/obj/lnd_gripper_link.obj"/>
      </geometry>
      <material name="">
        <color rgba="0.79608 0.82353 0.93725 1"/>
      </material>
    </visual>
    <collision name="tool_gripper1_link_collision_0">
      <origin rpy="0 0 0" xyz="0 0 0"/>
      <geometry>
        <mesh filename="package://meshes/obj/lnd_gripper_link_collision_0.obj"/>
      </geometry>
    </collision>
    <collision name="tool_gripper1_link_collision_1">
      <origin rpy="0 0 0" xyz="0 0 0"/>
      <geometry>
        <mesh filename="package://meshes/obj/lnd_gripper_link_collision_1.obj"/>
      </geometry>
    </collision>
  </link>

  <link name="tool_gripper2_link">
    <inertial>
      <origin rpy="0 0 0" xyz="-0.00019605 0.001435 0.00088478"/>
      <mass value="0.010491"/>
      <inertia ixx="0.001" ixy="0.00001" ixz="0.00001" iyy="0.001" iyz="0.00001" izz="0.001"/>
    </inertial>
    <visual>
      <origin rpy="0 3.1416 0" xyz="0 0 0"/>
      <geometry>
        <mesh filename="package://meshes/obj/lnd_gripper_link.obj"/>
      </geometry>
      <material name="">
        <color rgba="0.79608 0.82353 0.93725 1"/>
      </material>
    </visual>
    <collision name="tool_gripper2_link_collision_0">
      <origin rpy="0 3.1416 0" xyz="0 0 0"/>
      <geometry>
        <mesh filename="package://meshes/obj/lnd_gripper_link_collision_0.obj"/>
      </geometry>
    </collision>
    <collision name="tool_gripper2_link_collision_1">
      <origin rpy="0 3.1416 0" xyz="0 0 0"/>
      <geometry>
        <mesh filename="package://meshes/obj/lnd_gripper_link_collision_1.obj"/>
      </geometry>
    </collision>
  </link>

  <link name="tool_tip"/>

  <disable_collision link1="main_insertion_link" link2="tool_roll_link"/>
  <disable_collision link1="tool_roll_link" link2="tool_pitch_link"/>
  <disable_collision link1="tool_pitch_link" link2="tool_gripper1_link"/>
  <disable_collision link1="tool_pitch_link" link2="tool_gripper2_link"/>
  <disable_collision link1="tool_gripper1_link" link2="tool_gripper2_link"/>

</robot>
