<mujoco model="franka_lnd">
  <compiler angle="radian" meshdir="/path/to/meshes"/>

  <asset>
    <mesh name="link0" file="link0.obj"/>
    <mesh name="link1" file="link1.obj"/>
    <mesh name="link2" file="link2.obj"/>
    <mesh name="link3" file="link3.obj"/>
    <mesh name="link4" file="link4.obj"/>
    <mesh name="link5" file="link5.obj"/>
    <mesh name="link6" file="link6.obj"/>
    <mesh name="link7" file="link7.obj"/>
    <mesh name="franka_tool_mount" file="franka_tool_mount.obj"/>
    <mesh name="tool_main_insertion_link" file="tool_main_insertion_link.obj"/>
    <mesh name="tool_main_insertion_link_collision_0.test" file="tool_main_insertion_link_collision_0.test.obj"/>
    <mesh name="tool_main_insertion_link_collision_1.test" file="tool_main_insertion_link_collision_1.test.obj"/>
    <mesh name="lnd_roll_link" file="lnd_roll_link.obj"/>
    <mesh name="lnd_roll_link_collision_0.test" file="lnd_roll_link_collision_0.test.obj"/>
    <mesh name="lnd_roll_link_collision_1.test" file="lnd_roll_link_collision_1.test.obj"/>
    <mesh name="lnd_roll_link_collision_2.test" file="lnd_roll_link_collision_2.test.obj"/>
    <mesh name="lnd_pitch_link" file="lnd_pitch_link.obj"/>
    <mesh name="lnd_pitch_link_collision_0.test" file="lnd_pitch_link_collision_0.test.obj"/>
    <mesh name="lnd_pitch_link_collision_1.test" file="lnd_pitch_link_collision_1.test.obj"/>
    <mesh name="lnd_pitch_link_collision_2.test" file="lnd_pitch_link_collision_2.test.obj"/>
    <mesh name="lnd_yaw_link" file="lnd_yaw_link.obj"/>
    <mesh name="lnd_gripper_link" file="lnd_gripper_link.obj"/>
    <mesh name="lnd_gripper_link_collision_0.test" file="lnd_gripper_link_collision_0.test.obj"/>
    <mesh name="lnd_gripper_link_collision_1.test" file="lnd_gripper_link_collision_1.test.obj"/>
  </asset>

  <worldbody>
    <geom type="mesh" contype="0" conaffinity="0" group="1" density="0" mesh="link0"/>
    <body name="panda_link1" pos="0 0 0.333">
      <inertial pos="0.003875 0.002081 -0.04762" quat="0.711549 0.00634377 -0.0131124 0.702485" mass="4.97068" diaginertia="0.707137 0.703435 0.00852456"/>
      <joint name="panda_joint1" pos="0 0 0" axis="0 0 1" range="-2.9671 2.9671" actuatorfrcrange="-87 87" damping="0.003"/>
      <geom type="mesh" contype="0" conaffinity="0" group="1" density="0" mesh="link1"/>
      <body name="panda_link2" quat="0.707107 -0.707107 0 0">
        <inertial pos="-0.003141 -0.02872 0.003495" quat="-0.168175 0.828366 -0.122878 0.520027" mass="0.646926" diaginertia="0.0310326 0.0283001 0.00273425"/>
        <joint name="panda_joint2" pos="0 0 0" axis="0 0 1" range="-1.8326 1.8326" actuatorfrcrange="-87 87" damping="0.003"/>
        <geom type="mesh" contype="0" conaffinity="0" group="1" density="0" mesh="link2"/>
        <body name="panda_link3" pos="0 -0.316 0" quat="0.707107 0.707107 0 0">
          <inertial pos="0.027518 0.039252 -0.066502" quat="0.662769 -0.00678331 0.252053 0.705096" mass="3.2286" diaginertia="0.0415014 0.0414793 0.00124635"/>
          <joint name="panda_joint3" pos="0 0 0" axis="0 0 1" range="-2.9671 2.9671" actuatorfrcrange="-87 87" damping="0.003"/>
          <geom type="mesh" contype="0" conaffinity="0" group="1" density="0" mesh="link3"/>
          <body name="panda_link4" pos="0.0825 0 0" quat="0.707107 0.707107 0 0">
            <inertial pos="-0.05317 0.104419 0.027454" quat="0.65058 0.529822 -0.0962034 0.535518" mass="3.5879" diaginertia="0.0349596 0.0281483 0.0106201"/>
            <joint name="panda_joint4" pos="0 0 0" axis="0 0 1" range="-3.1416 -0.4" actuatorfrcrange="-87 87" damping="0.003"/>
            <geom type="mesh" contype="0" conaffinity="0" group="1" density="0" mesh="link4"/>
            <body name="panda_link5" pos="-0.0825 0.384 0" quat="0.707107 -0.707107 0 0">
              <inertial pos="-0.011953 0.041065 -0.038437" quat="0.987313 -0.0121954 0.0719187 -0.141037" mass="1.22595" diaginertia="0.0367625 0.0288531 0.00803437"/>
              <joint name="panda_joint5" pos="0 0 0" axis="0 0 1" range="-2.9671 2.9671" actuatorfrcrange="-12 12" damping="0.003"/>
              <geom type="mesh" contype="0" conaffinity="0" group="1" density="0" mesh="link5"/>
              <body name="panda_link6" quat="0.707107 0.707107 0 0">
                <inertial pos="0.060149 -0.014117 -0.010517" quat="0.101075 0.59332 0.0287227 0.798079" mass="1.66656" diaginertia="0.00584276 0.00431037 0.00159787"/>
                <joint name="panda_joint6" pos="0 0 0" axis="0 0 1" range="-0.0873 3.8223" actuatorfrcrange="-12 12" damping="0.003"/>
                <geom type="mesh" contype="0" conaffinity="0" group="1" density="0" mesh="link6"/>
                <body name="panda_link7" pos="0.088 0 0" quat="0.707107 0.707107 0 0">
                  <inertial pos="0.00270178 -0.00323068 0.0943265" quat="0.995438 -0.0508776 0.015644 -0.0791877" mass="0.960432" diaginertia="0.0199581 0.0176088 0.00891056"/>
                  <joint name="panda_joint7" pos="0 0 0" axis="0 0 1" range="-2.9671 2.9671" actuatorfrcrange="-12 12" damping="0.003"/>
                  <geom type="mesh" contype="0" conaffinity="0" group="1" density="0" mesh="link7"/>
                  <geom pos="-0.0188 0 0.1915" quat="1.32679e-06 0 0 1" type="mesh" contype="0" conaffinity="0" group="1" density="0" mesh="franka_tool_mount"/>
                  <geom pos="-0.0188 0 0.1915" quat="1.32679e-06 0 0 1" type="mesh" contype="0" conaffinity="0" group="1" density="0" rgba="0.3 0.3 0.3 1" mesh="tool_main_insertion_link"/>
                  <!-- geom name="main_insertion_link_collision_0" pos="-0.0188 0 0.1915" quat="1.32679e-06 0 0 1" type="mesh" rgba="0.3 0.3 0.3 1" mesh="tool_main_insertion_link_collision_0.test"/ -->
                  <!-- geom name="main_insertion_link_collision_1" pos="-0.0188 0 0.1915" quat="1.32679e-06 0 0 1" type="mesh" rgba="0.3 0.3 0.3 1" mesh="tool_main_insertion_link_collision_1.test"/ -->
                  <body name="tool_roll_link" pos="-0.0188 0 0.6077" quat="1.32679e-06 0 0 1">
                    <inertial pos="0 0 -0.0058234" quat="0.820473 0.339851 -0.17592 0.424708" mass="0.00033225" diaginertia="0.00102 0.00099 0.00099"/>
                    <joint name="tool_roll" pos="0 0 0" axis="0 0 1" range="-3.14159 3.14159" actuatorfrcrange="-1000 1000"/>
                    <geom type="mesh" contype="0" conaffinity="0" group="1" density="0" rgba="0.79608 0.82353 0.93725 1" mesh="lnd_roll_link"/>
                    <!-- geom name="tool_roll_link_collision_0" type="mesh" rgba="0.79608 0.82353 0.93725 1" mesh="lnd_roll_link_collision_0.test"/ -->
                    <!-- geom name="tool_roll_link_collision_1" type="mesh" rgba="0.79608 0.82353 0.93725 1" mesh="lnd_roll_link_collision_1.test"/ -->
                    <!-- geom name="tool_roll_link_collision_2" type="mesh" rgba="0.79608 0.82353 0.93725 1" mesh="lnd_roll_link_collision_2.test"/ -->
                    <body name="tool_pitch_link" quat="0.499998 0.5 -0.5 0.500002">
                      <inertial pos="0.0035763 0 0" quat="0.820473 0.339851 -0.17592 0.424708" mass="0.00025784" diaginertia="0.00102 0.00099 0.00099"/>
                      <joint name="tool_pitch" pos="0 0 0" axis="0 0 1" range="-1.5708 1.5708" actuatorfrcrange="-1000 1000"/>
                      <geom type="mesh" contype="0" conaffinity="0" group="1" density="0" rgba="0.79608 0.82353 0.93725 1" mesh="lnd_pitch_link"/>
                      <!-- geom name="tool_pitch_link_collision_0" type="mesh" rgba="0.79608 0.82353 0.93725 1" mesh="lnd_pitch_link_collision_0.test"/ -->
                      <!-- geom name="tool_pitch_link_collision_1" type="mesh" rgba="0.79608 0.82353 0.93725 1" mesh="lnd_pitch_link_collision_1.test"/ -->
                      <!-- geom name="tool_pitch_link_collision_2" type="mesh" rgba="0.79608 0.82353 0.93725 1" mesh="lnd_pitch_link_collision_2.test"/ -->
                      <body name="tool_yaw_link" pos="0.0091 0 0" quat="0.499998 -0.5 0.5 0.500002">
                        <inertial pos="0 0 0" quat="0.820473 0.339851 -0.17592 0.424708" mass="0.012491" diaginertia="0.00102 0.00099 0.00099"/>
                        <joint name="tool_yaw" pos="0 0 0" axis="0 0 1" range="-1.5708 1.5708" actuatorfrcrange="-1000 1000"/>
                        <geom type="mesh" contype="0" conaffinity="0" group="1" density="0" rgba="0.79608 0.82353 0.93725 1" mesh="lnd_yaw_link"/>
                        <body name="tool_gripper1_link">
                          <inertial pos="0.00019605 0.001435 -0.00088478" quat="0.820473 0.339851 -0.17592 0.424708" mass="0.010491" diaginertia="0.00102 0.00099 0.00099"/>
                          <joint name="tool_gripper1_joint" pos="0 0 0" axis="0 0 1" range="-1 0"/>
                          <geom type="mesh" contype="0" conaffinity="0" group="1" density="0" rgba="0.79608 0.82353 0.93725 1" mesh="lnd_gripper_link"/>
                          <!-- geom name="tool_gripper1_link_collision_0" type="mesh" rgba="0.79608 0.82353 0.93725 1" mesh="lnd_gripper_link_collision_0.test"/ -->
                          <!-- geom name="tool_gripper1_link_collision_1" type="mesh" rgba="0.79608 0.82353 0.93725 1" mesh="lnd_gripper_link_collision_1.test"/ -->
                        </body>
                        <body name="tool_gripper2_link">
                          <inertial pos="-0.00019605 0.001435 0.00088478" quat="0.820473 0.339851 -0.17592 0.424708" mass="0.010491" diaginertia="0.00102 0.00099 0.00099"/>
                          <joint name="jaw" pos="0 0 0" axis="0 0 1" range="0 1"/>
                          <geom quat="-3.67321e-06 0 1 0" type="mesh" contype="0" conaffinity="0" group="1" density="0" rgba="0.79608 0.82353 0.93725 1" mesh="lnd_gripper_link"/>
                          <!-- geom name="tool_gripper2_link_collision_0" quat="-3.67321e-06 0 1 0" type="mesh" rgba="0.79608 0.82353 0.93725 1" mesh="lnd_gripper_link_collision_0.test"/ -->
                          <!-- geom name="tool_gripper2_link_collision_1" quat="-3.67321e-06 0 1 0" type="mesh" rgba="0.79608 0.82353 0.93725 1" mesh="lnd_gripper_link_collision_1.test"/ -->
                        </body>
                      </body>
                    </body>
                  </body>
                </body>
              </body>
            </body>
          </body>
        </body>
      </body>
    </body>
  </worldbody>
</mujoco>
